Workbook

Sheet 2026 US30
A1: DATE | B1: FVP HIGH NODE | C1: FVP MED NODE | D1: FVP LOW NODE | E1: VWAP | F1: WIN OR LOSS | G1: AGAINST 4HR WICK | H1: RATING | I1: ADJ RISK (XLOOKUP) | J1: WIN RATE % (VLOOKUP) | K1: BUY OR SELL | L1: ROI | M1: Cumulative ROI | N1: TRADE PROFIT / LOSS | O1: ACCOUNT BALANCE
A2: JAN 6TH | B2: Y | E2: Y | F2: W | H2: B | I2: =_xlfn.XLOOKUP(IF(OR(H2="D", H2="F"), "D&F TRADES", H2 & " TRADES"), $C$32:$C$35, $A$32:$A$35, "N/A") -> 1 | J2: =VLOOKUP(IF(OR(H2="D", H2="F"), "D&F TRADES", H2 & " TRADES"), $C$32:$G$35, 5, FALSE) -> 0.55555556 | K2: BUY | L2: 2 | M2: =L2 -> 2 | N2: 2000 | O2: 102000
A3: JAN 15TH | D3: Y | E3: N | F3: W | H3: B | I3: =_xlfn.XLOOKUP(IF(OR(H3="D", H3="F"), "D&F TRADES", H3 & " TRADES"), $C$32:$C$35, $A$32:$A$35, "N/A") -> 1 | J3: =VLOOKUP(IF(OR(H3="D", H3="F"), "D&F TRADES", H3 & " TRADES"), $C$32:$G$35, 5, FALSE) -> 0.55555556 | K3: BUY | L3: 2 | M3: =M2+L3 -> 4 | N3: 2000 | O3: =O2+N3 -> 104000
A4: FEB 4TH | B4: Y | E4: N | F4: L | H4: D | I4: =_xlfn.XLOOKUP(IF(OR(H4="D", H4="F"), "D&F TRADES", H4 & " TRADES"), $C$32:$C$35, $A$32:$A$35, "N/A") -> 0.1 | J4: =VLOOKUP(IF(OR(H4="D", H4="F"), "D&F TRADES", H4 & " TRADES"), $C$32:$G$35, 5, FALSE) -> 0.22222222 | K4: BUY | L4: -1 | M4: =M3+L4 -> 3 | N4: -1000 | O4: =O3+N4 -> 103000
A5: FEB 4TH | B5: Y | E5: Y PARTLY | F5: W | H5: C | I5: =_xlfn.XLOOKUP(IF(OR(H5="D", H5="F"), "D&F TRADES", H5 & " TRADES"), $C$32:$C$35, $A$32:$A$35, "N/A") -> 1 | J5: =VLOOKUP(IF(OR(H5="D", H5="F"), "D&F TRADES", H5 & " TRADES"), $C$32:$G$35, 5, FALSE) -> 1 | K5: BUY | L5: 2 | M5: =M4+L5 -> 5 | N5: 2000 | O5: =O4+N5 -> 105000
A6: FEB 12TH | D6: Y | E6: Y PARTLY | F6: L | G6: Y | H6: F | I6: =_xlfn.XLOOKUP(IF(OR(H6="D", H6="F"), "D&F TRADES", H6 & " TRADES"), $C$32:$C$35, $A$32:$A$35, "N/A") -> 0.1 | J6: =VLOOKUP(IF(OR(H6="D", H6="F"), "D&F TRADES", H6 & " TRADES"), $C$32:$G$35, 5, FALSE) -> 0.22222222 | K6: BUY | L6: -1 | M6: =M5+L6 -> 4 | N6: -1000 | O6: =O5+N6 -> 104000
A7: MARCH 11TH | D7: Y | E7: Y | F7: W | H7: A | I7: =_xlfn.XLOOKUP(IF(OR(H7="D", H7="F"), "D&F TRADES", H7 & " TRADES"), $C$32:$C$35, $A$32:$A$35, "N/A") -> 2 | J7: =VLOOKUP(IF(OR(H7="D", H7="F"), "D&F TRADES", H7 & " TRADES"), $C$32:$G$35, 5, FALSE) -> 0.8 | K7: SELL | L7: 2 | M7: =M6+L7 -> 6 | N7: 2000 | O7: =O6+N7 -> 106000
A8: APRIL 2ND | D8: Y | E8: N | F8: W | H8: B | I8: =_xlfn.XLOOKUP(IF(OR(H8="D", H8="F"), "D&F TRADES", H8 & " TRADES"), $C$32:$C$35, $A$32:$A$35, "N/A") -> 1 | J8: =VLOOKUP(IF(OR(H8="D", H8="F"), "D&F TRADES", H8 & " TRADES"), $C$32:$G$35, 5, FALSE) -> 0.55555556 | K8: BUY | L8: 2 | M8: =M7+L8 -> 8 | N8: 2000 | O8: =O7+N8 -> 108000
A9: APRIL 8TH | D9: Y | E9: N | F9: W | H9: B | I9: =_xlfn.XLOOKUP(IF(OR(H9="D", H9="F"), "D&F TRADES", H9 & " TRADES"), $C$32:$C$35, $A$32:$A$35, "N/A") -> 1 | J9: =VLOOKUP(IF(OR(H9="D", H9="F"), "D&F TRADES", H9 & " TRADES"), $C$32:$G$35, 5, FALSE) -> 0.55555556 | K9: BUY | L9: 2 | M9: =M8+L9 -> 10 | N9: 2000 | O9: =O8+N9 -> 110000
A10: MAY 11TH | C10: Y | E10: Y | F10: L | H10: B | I10: =_xlfn.XLOOKUP(IF(OR(H10="D", H10="F"), "D&F TRADES", H10 & " TRADES"), $C$32:$C$35, $A$32:$A$35, "N/A") -> 1 | J10: =VLOOKUP(IF(OR(H10="D", H10="F"), "D&F TRADES", H10 & " TRADES"), $C$32:$G$35, 5, FALSE) -> 0.55555556 | K10: BUY | L10: -1 | M10: =M9+L10 -> 9 | N10: -1000 | O10: =O9+N10 -> 109000
A11: MAY 11TH | C11: Y | E11: Y | F11: L | H11: B | I11: =_xlfn.XLOOKUP(IF(OR(H11="D", H11="F"), "D&F TRADES", H11 & " TRADES"), $C$32:$C$35, $A$32:$A$35, "N/A") -> 1 | J11: =VLOOKUP(IF(OR(H11="D", H11="F"), "D&F TRADES", H11 & " TRADES"), $C$32:$G$35, 5, FALSE) -> 0.55555556 | K11: BUY | L11: -1 | M11: =M10+L11 -> 8 | N11: -1000 | O11: =O10+N11 -> 108000
A12: MAY 13TH | D12: Y | E12: Y PARTLY | F12: W | H12: B | I12: =_xlfn.XLOOKUP(IF(OR(H12="D", H12="F"), "D&F TRADES", H12 & " TRADES"), $C$32:$C$35, $A$32:$A$35, "N/A") -> 1 | J12: =VLOOKUP(IF(OR(H12="D", H12="F"), "D&F TRADES", H12 & " TRADES"), $C$32:$G$35, 5, FALSE) -> 0.55555556 | K12: SELL | L12: 3.5 | M12: =M11+L12 -> 11.5 | N12: 3500 | O12: =O11+N12 -> 111500
A13: MAY 25TH | D13: Y | E13: Y | F13: L | H13: A | I13: =_xlfn.XLOOKUP(IF(OR(H13="D", H13="F"), "D&F TRADES", H13 & " TRADES"), $C$32:$C$35, $A$32:$A$35, "N/A") -> 2 | J13: =VLOOKUP(IF(OR(H13="D", H13="F"), "D&F TRADES", H13 & " TRADES"), $C$32:$G$35, 5, FALSE) -> 0.8 | K13: BUY | L13: -1 | M13: =M12+L13 -> 10.5 | N13: -1000 | O13: =O12+N13 -> 110500
A14: MAY 27TH | B14: Y | E14: N | F14: W | H14: D | I14: =_xlfn.XLOOKUP(IF(OR(H14="D", H14="F"), "D&F TRADES", H14 & " TRADES"), $C$32:$C$35, $A$32:$A$35, "N/A") -> 0.1 | J14: =VLOOKUP(IF(OR(H14="D", H14="F"), "D&F TRADES", H14 & " TRADES"), $C$32:$G$35, 5, FALSE) -> 0.22222222 | K14: BUY | L14: 3.5 | M14: =M13+L14 -> 14 | N14: 3500 | O14: =O13+N14 -> 114000
A15: MAY 29TH | D15: Y | E15: Y | F15: W | H15: A | I15: =_xlfn.XLOOKUP(IF(OR(H15="D", H15="F"), "D&F TRADES", H15 & " TRADES"), $C$32:$C$35, $A$32:$A$35, "N/A") -> 2 | J15: =VLOOKUP(IF(OR(H15="D", H15="F"), "D&F TRADES", H15 & " TRADES"), $C$32:$G$35, 5, FALSE) -> 0.8 | K15: BUY | L15: 2 | M15: =M14+L15 -> 16 | N15: 2000 | O15: =O14+N15 -> 116000
A16: JUNE 1ST | D16: Y | E16: N | F16: L | H16: B | I16: =_xlfn.XLOOKUP(IF(OR(H16="D", H16="F"), "D&F TRADES", H16 & " TRADES"), $C$32:$C$35, $A$32:$A$35, "N/A") -> 1 | J16: =VLOOKUP(IF(OR(H16="D", H16="F"), "D&F TRADES", H16 & " TRADES"), $C$32:$G$35, 5, FALSE) -> 0.55555556 | K16: BUY | L16: -1 | M16: =M15+L16 -> 15 | N16: -1000 | O16: =O15+N16 -> 115000
A17: JUNE 9TH | D17: Y | E17: N | F17: L | G17: Y | H17: F | I17: =_xlfn.XLOOKUP(IF(OR(H17="D", H17="F"), "D&F TRADES", H17 & " TRADES"), $C$32:$C$35, $A$32:$A$35, "N/A") -> 0.1 | J17: =VLOOKUP(IF(OR(H17="D", H17="F"), "D&F TRADES", H17 & " TRADES"), $C$32:$G$35, 5, FALSE) -> 0.22222222 | K17: BUY | L17: -1 | M17: =M16+L17 -> 14 | N17: -1000 | O17: =O16+N17 -> 114000
A18: JUNE 11TH | B18: Y | E18: N | F18: L | H18: D | I18: =_xlfn.XLOOKUP(IF(OR(H18="D", H18="F"), "D&F TRADES", H18 & " TRADES"), $C$32:$C$35, $A$32:$A$35, "N/A") -> 0.1 | J18: =VLOOKUP(IF(OR(H18="D", H18="F"), "D&F TRADES", H18 & " TRADES"), $C$32:$G$35, 5, FALSE) -> 0.22222222 | K18: BUY | L18: -1 | M18: =M17+L18 -> 13 | N18: -1000 | O18: =O17+N18 -> 113000
A19: JUNE 11TH | B19: Y | E19: N | F19: W | H19: D | I19: =_xlfn.XLOOKUP(IF(OR(H19="D", H19="F"), "D&F TRADES", H19 & " TRADES"), $C$32:$C$35, $A$32:$A$35, "N/A") -> 0.1 | J19: =VLOOKUP(IF(OR(H19="D", H19="F"), "D&F TRADES", H19 & " TRADES"), $C$32:$G$35, 5, FALSE) -> 0.22222222 | K19: BUY | L19: 2 | M19: =M18+L19 -> 15 | N19: 2000 | O19: =O18+N19 -> 115000
A20: JUNE 29TH | D20: Y | E20: Y | F20: L | G20: Y | H20: F | I20: =_xlfn.XLOOKUP(IF(OR(H20="D", H20="F"), "D&F TRADES", H20 & " TRADES"), $C$32:$C$35, $A$32:$A$35, "N/A") -> 0.1 | J20: =VLOOKUP(IF(OR(H20="D", H20="F"), "D&F TRADES", H20 & " TRADES"), $C$32:$G$35, 5, FALSE) -> 0.22222222 | K20: BUY | L20: -1 | M20: =M19+L20 -> 14 | N20: -1000 | O20: =O19+N20 -> 114000
A21: JUNE 30TH | D21: Y | E21: Y | F21: L | G21: Y | H21: F | I21: =_xlfn.XLOOKUP(IF(OR(H21="D", H21="F"), "D&F TRADES", H21 & " TRADES"), $C$32:$C$35, $A$32:$A$35, "N/A") -> 0.1 | J21: =VLOOKUP(IF(OR(H21="D", H21="F"), "D&F TRADES", H21 & " TRADES"), $C$32:$G$35, 5, FALSE) -> 0.22222222 | K21: BUY | L21: -1 | M21: =M20+L21 -> 13 | N21: -1000 | O21: =O20+N21 -> 113000
A22: JULY 31TH | D22: Y | E22: Y | F22: W | H22: A | I22: =_xlfn.XLOOKUP(IF(OR(H22="D", H22="F"), "D&F TRADES", H22 & " TRADES"), $C$32:$C$35, $A$32:$A$35, "N/A") -> 2 | J22: =VLOOKUP(IF(OR(H22="D", H22="F"), "D&F TRADES", H22 & " TRADES"), $C$32:$G$35, 5, FALSE) -> 0.8 | K22: SELL | L22: 2 | M22: =M21+L22 -> 15 | N22: 2000 | O22: =O21+N22 -> 115000
A23: AUGUST 5TH | D23: Y | E23: Y | F23: W | H23: A | I23: =_xlfn.XLOOKUP(IF(OR(H23="D", H23="F"), "D&F TRADES", H23 & " TRADES"), $C$32:$C$35, $A$32:$A$35, "N/A") -> 2 | J23: =VLOOKUP(IF(OR(H23="D", H23="F"), "D&F TRADES", H23 & " TRADES"), $C$32:$G$35, 5, FALSE) -> 0.8 | K23: BUY | L23: 3.5 | M23: =M22+L23 -> 18.5 | N23: 3500 | O23: =O22+N23 -> 118500
A24: AUGUST 7TH | B24: Y | E24: Y | F24: L | H24: B | I24: =_xlfn.XLOOKUP(IF(OR(H24="D", H24="F"), "D&F TRADES", H24 & " TRADES"), $C$32:$C$35, $A$32:$A$35, "N/A") -> 1 | J24: =VLOOKUP(IF(OR(H24="D", H24="F"), "D&F TRADES", H24 & " TRADES"), $C$32:$G$35, 5, FALSE) -> 0.55555556 | K24: BUY | L24: -1 | M24: =M23+L24 -> 17.5 | N24: -1000 | O24: =O23+N24 -> 117500
A25: SEPT 11TH | D25: Y | E25: Y | F25: L | G25: Y | H25: F | I25: =_xlfn.XLOOKUP(IF(OR(H25="D", H25="F"), "D&F TRADES", H25 & " TRADES"), $C$32:$C$35, $A$32:$A$35, "N/A") -> 0.1 | J25: =VLOOKUP(IF(OR(H25="D", H25="F"), "D&F TRADES", H25 & " TRADES"), $C$32:$G$35, 5, FALSE) -> 0.22222222 | K25: BUY | L25: -1 | M25: =M24+L25 -> 16.5 | N25: -1000 | O25: =O24+N25 -> 116500
K27: ROI BEFORE L | L27: =SUM(L2:L25) -> 16.5
K28: ROI AFTER L | L28: =L27-E36 -> 4.5
B31: ADJ RISK | C31: SETUP RATING | D31: AMOUNT | E31: WIN | F31: LOSS | G31: WIN RATE | H31: WINS RETURN 1 R PER TRADE BEFORE LOSSES | K31: RISK ON ALL TRADES | L31: ADJ RISK PER TRADE WINS - LOSSES/ NET ROI | M31: Max Win streak
A32: 2 | B32: 2 | C32: A TRADES | D32: =COUNTIF(H2:H25, "A" ) -> 5 | E32: =COUNTIFS(F2:F25, "W", H2:H25, "A") -> 4 | F32: =COUNTIFS(F2:F25, "L", H2:H25, "A" ) -> 1 | G32: =E32/D32 -> 0.8 | H32: =SUMIF(H2:H25, "A", L2:L25) -> 8.5 | K32: =D32*B32 -> 10 | L32: =H32*B32-F32*B32 -> 15
A33: 1 | B33: 1 | C33: B TRADES | D33: =COUNTIF(H2:H25, "B" ) -> 9 | E33: =COUNTIFS(F2:F25, "W", H2:H25, "B" ) -> 5 | F33: =COUNTIFS(F2:F25, "L", H2:H25, "B" ) -> 4 | G33: =E33/D33 -> 0.55555556 | H33: =SUMIF(H2:H25, "B", L2:L25) -> 7.5 | K33: =D33*B33 -> 9 | L33: =H33*B33-F33*B33 -> 3.5
A34: 1 | B34: 1 | C34: C TRADES | D34: =COUNTIF(H2:H25, "C" ) -> 1 | E34: =COUNTIFS(F2:F25, "W", H2:H25, "C") -> 1 | F34: =COUNTIFS(F2:F25, "L", H2:H25, "C") -> 0 | G34: =E34/D34 -> 1 | H34: =SUMIF(H2:H25, "C", L2:L25) -> 2 | K34: =D34*B34 -> 1 | L34: =H34*B34-F34*B34 -> 2
A35: 0.1 | B35: 0.1 | C35: D&F TRADES | D35: =COUNTIF(H2:H25, "D" ) + COUNTIF(H2:H25, "F") -> 9 | E35: =COUNTIFS(F2:F25, "W", H2:H25, "D") + COUNTIFS(F2:F25, "W", H2:H25, "F") -> 2 | F35: =COUNTIFS(F2:F25, "L", H2:H25, "D") + COUNTIFS(F2:F25, "L", H2:H25, "F") -> 7 | G35: =E35/D35 -> 0.22222222 | H35: =SUMIF(H2:H25,"D",L2:L25)+SUMIF(H2:H25,"F",L2:L25) -> -1.5 | K35: =D35*B35 -> 0.9 | L35: =H35*B35-F35*B35 -> -0.85
C36: SUMS A-F | D36: =SUM(D32:D35) -> 24 | E36: =SUM(E32:E35) -> 12
D37: =SUM(D32:D34) -> 15 | E37: =SUM(E32:E34) -> 10
E39: WIN RATE BEFORE ADJ (A-FTRADES) | F39: =E36/D36*100 -> 50 | K39: ADJ ROI | L39: =SUM(L32:L35) -> 19.65
G40: 16% INCREASE
E41: WIN RATE AFTER ADJ (A-C) trades | F41: =E37/D37*100 -> 66.666667 | K41: NET ADJ ROI | L41: =L39-L28 -> 15.15
D46: SETUP RATING | E46: ADJ RISK PER TRADE WINS - LOSSES/ NET ROI
D47: A TRADES | E47: =H32*B32-F32*B32 -> 15
D48: B TRADES | E48: =H33*B33-F33*B33 -> 3.5
...

Sheet Executive Dashboard
B2: Ending Portfolio Value | D2: Net Dollar Return | F2: Total Return (%) | H2: Overall Win Rate
B3: ='2026 US30'!O25 -> 116500 | D3: 16500 | F3: 0.165 | H3: 0.5

Sheet Financial Modelling 
C2: Starting Capital | D2: 100000
C3: Risk Per trade % | D3: 0.01
C4: Risk Per trade $ | D4: =D2*D3 -> 1000
C5: Model Horizon ( Trades)
C12: ADJ RISK | D12: SETUP RATING | E12: AMOUNT | F12: WIN | G12: LOSS | H12: WIN RATE | I12: WINS RETURN 1 R PER TRADE BEFORE LOSSES | J12: RISK ON ALL TRADES | K12: ADJ RISK PER TRADE WINS - LOSSES/ NET ROI | L12: Max Win streak
C13: 2 | D13: A TRADES | E13: =COUNTIF('2026 US30'!H:H, "A") -> 5 | F13: =COUNTIFS('2026 US30'!H:H, "A", '2026 US30'!F:F, "W") -> 4 | G13: =COUNTIFS('2026 US30'!H:H, "A", '2026 US30'!F:F, "L") -> 1 | H13: =F13/E13*100 -> 80 | I13: =SUMIF('2026 US30'!H:H, "A", '2026 US30'!L:L) -> 8.5 | J13: =E13*C13 -> 10 | K13: =I13*C13-G13*C13 -> 15
C14: 1 | D14: B TRADES | E14: =COUNTIF('2026 US30'!H:H, "B") -> 9 | F14: =COUNTIFS('2026 US30'!H:H, "B", '2026 US30'!F:F, "W") -> 5 | G14: =COUNTIFS('2026 US30'!H:H, "B", '2026 US30'!F:F, "L") -> 4 | H14: =F14/E14*100 -> 55.555556 | I14: =SUMIF('2026 US30'!H:H, "B", '2026 US30'!L:L) -> 7.5 | J14: =E14*C14 -> 9 | K14: =I14*C14-G14*C14 -> 3.5
C15: 1 | D15: C TRADES | E15: =COUNTIF('2026 US30'!H:H, "C") -> 1 | F15: =COUNTIFS('2026 US30'!H:H, "C", '2026 US30'!F:F, "W") -> 1 | G15: =COUNTIFS('2026 US30'!H:H, "C", '2026 US30'!F:F, "L") -> 0 | H15: =F15/E15*100 -> 100 | I15: =SUMIF('2026 US30'!H:H, "C", '2026 US30'!L:L) -> 2 | J15: =E15*C15 -> 1 | K15: =I15*C15-G15*C15 -> 2
C16: 0.1 | D16: D&F TRADES | E16: =COUNTIF('2026 US30'!H:H, "D") + COUNTIF('2026 US30'!H:H, "F") -> 9 | F16: =COUNTIFS('2026 US30'!H:H, "D", '2026 US30'!F:F, "W") + COUNTIFS('2026 US30'!H:H, "F", '2026 US30'!F:F, "W") -> 2 | G16: =COUNTIFS('2026 US30'!H:H, "D", '2026 US30'!F:F, "L") + COUNTIFS('2026 US30'!H:H, "F", '2026 US30'!F:F, "L") -> 7 | H16: =F16/E16*100 -> 22.222222 | I16: =SUMIF('2026 US30'!H:H, "D", '2026 US30'!L:L) + SUMIF('2026 US30'!H:H, "F", '2026 US30'!L:L) -> -1.5 | J16: =E16*C16 -> 0.9 | K16: =I16*C16-G16*C16 -> -0.85
B18: Base Case (Actual Portfolio Balance) | C18: ='2026 US30'!O25 -> 116500
B19: Optimized Case (Filter D/F Setups) | C19: =$D$2+((I13+I14+I15)*$D$4) -> 118000
B20: Stress Test (-10% Win Rate) | C20: =C18-(0.1*SUM(E13:E16)*$D$4) -> 114100

Sheet README
A1: ===============================================================
A2: FINANCIAL MODEL & TRADING PERFORMANCE ANALYTICS DASHBOARD
A3: ===============================================================
A5: 1. OVERVIEW
A6: - Capital Base: $100,000 starting portfolio balance.
A7: - Fixed Risk Model: 1% risk per trade execution ($1,000 / 1R).
A8: - Core Instrument: 2026 US30 Execution Log.
A10: 2. WORKBOOK ARCHITECTURE
A11: - Executive Dashboard: High-level C-Suite KPI metrics, portfolio equity curve, and setup performance breakdown.
A12: - Financial Modelling: Dynamic financial inputs, tier-based performance distribution, and 3-scenario stress testing.
A13: - 2026 US30: Core operational trade log with R-multipliers, position sizing, dollar profit/loss, and compounding balance engine.
A14: - README: Model documentation, structure overview, and methodology.
... A19: - Stress Case: Evaluates portfolio resilience by simulating a 10% win-rate reduction ($114,100.00).

Sheet 2025 US 30
A1: DATE | B1: FVP HIGH NODE | C1: FVP MED NODE | D1: FVP LOW NODE | E1: VWAP | F1: WIN OR LOSS | G1: AGAINST 4HR WICK | H1: RATING | I1: BUY OR SELL | J1: ROI | K1: CUMULATIVE ROI
A2: DEC 11TH | D2: Y | E2: Y | F2: W | H2: A* | I2: BUY | J2: 2 | K2: =J2 -> 2
A3: DEC 16TH | B3: Y | E3: N | F3: L | H3: D | I3: BUY | J3: -1 | K3: =K2+J3 -> 1
A4: DEC 24TH | D4: Y | E4: Y | F4: W | G4: Y | H4: F | I4: BUY | J4: 2 | K4: =K3+J4 -> 3
A5: DEC 26TH | C5: Y | E5: N | F5: W | H5: C | I5: BUY | J5: 3.5 | K5: =K4+J5 -> 6.5
A6: NOV 5TH | B6: Y | E6: N | F6: L | H6: D | I6: SELL | J6: -1 | K6: =K5+J6 -> 5.5
A7: OCT 31ST | B7: Y | E7: Y PARTLY | F7: L | H7: C | I7: BUY | J7: -1 | K7: =K6+J7 -> 4.5
A8: OCT 29TH | D8: Y | E8: N | F8: L | H8: B | I8: BUY | J8: -1 | K8: =K7+J8 -> 3.5
A9: OCT 23RD | B9: Y | E9: N | F9: W | H9: D | I9: BUY | J9: 3.5 | K9: =K8+J9 -> 7
A10: SEPT 19TH | D10: Y | E10: N | F10: L | H10: B | I10: BUY | J10: -1 | K10: =K9+J10 -> 6
A11: SEPT 11TH | D11: Y | E11: Y | F11: W | H11: A | I11: BUY | J11: 3.5 | K11: =K10+J11 -> 9.5
A12: SEPT 3RD | B12: Y | E12: N | F12: L | H12: D | I12: BUY | J12: -1 | K12: =K11+J12 -> 8.5
A13: AUG 5TH | B13: Y | E13: N | F13: L | H13: D | I13: SELL | J13: -1 | K13: =K12+J13 -> 7.5
A14: AUG 5TH | B14: Y | E14: Y | F14: L | H14: B | I14: SELL | J14: -1 | K14: =K13+J14 -> 6.5
A15: JULY 31ST | D15: Y | E15: Y | F15: L | G15: Y | H15: A | I15: SELL | J15: -1 | K15: =K14+J15 -> 5.5
A16: JULY 31ST | D16: Y | E16: Y | F16: W | G16: Y | H16: A | I16: SELL | J16: 2 | K16: =K15+J16 -> 7.5
A17: JULY 15TH | B17: Y | E17: Y | F17: W | H17: B | I17: SELL | J17: 2 | K17: =K16+J17 -> 9.5
A18: JULY 8TH | B18: Y | E18: N | F18: L | H18: D | I18: SELL | J18: -1 | K18: =K17+J18 -> 8.5
A19: JUNE 24TH | B19: Y | E19: N | F19: L | H19: D | I19: BUY | J19: -1 | K19: =K18+J19 -> 7.5
A20: JUNE 24TH | D20: Y | E20: N | F20: W | H20: B | I20: BUY | J20: 2 | K20: =K19+J20 -> 9.5
A21: JUNE 3RD | D21: Y | E21: N | F21: W | H21: B | I21: BUY | J21: 3.5 | K21: =K20+J21 -> 13
A22: MAY 30TH | B22: Y | E22: N | F22: L | G22: Y | H22: D | I22: SELL | J22: -1 | K22: =K21+J22 -> 12
A23: MAY 29TH | D23: Y | E23: Y | F23: W | H23: A | I23: SELL | J23: 2 | K23: =K22+J23 -> 14
A24: MAY 21ST | D24: Y | E24: N | F24: W | H24: B | I24: SELL | J24: 2 | K24: =K23+J24 -> 16
A25: MAY 13TH | B25: Y | E25: N | F25: W | H25: B | I25: SELL | J25: 3.5 | K25: =K24+J25 -> 19.5
A26: MAY 1ST | D26: Y | E26: N | F26: W | H26: B | I26: BUY | J26: 2 | K26: =K25+J26 -> 21.5
A27: APRIL 25TH | D27: Y | E27: Y | F27: L | H27: A | I27: SELL | J27: -1 | K27: =K26+J27 -> 20.5
A28: APRIL 21ST | D28: Y | E28: Y | F28: W | G28: Y | H28: A | I28: SELL | J28: 2 | K28: =K27+J28 -> 22.5
A29: MARCH 31ST | B29: Y | E29: Y | F29: W | H29: B | I29: BUY | J29: 2 | K29: =K28+J29 -> 24.5
A30: MARCH 27TH | B30: Y | E30: N | F30: W | H30: D | I30: SELL | J30: 2 | K30: =K29+J30 -> 26.5
A31: MARCH 26TH | D31: Y | E31: Y | F31: L | G31: Y | H31: F | I31: BUY | J31: -1 | K31: =K30+J31 -> 25.5
A32: FEB 21ST | D32: Y | E32: Y | F32: W | H32: A | I32: SELL | J32: 3.5 | K32: =K31+J32 -> 29
A33: FEB 19TH | B33: Y | E33: N | F33: W | H33: D | I33: SELL | J33: 3.5 | K33: =K32+J33 -> 32.5
A34: FEB 17TH | B34: Y | E34: Y | F34: L | H34: B | I34: BUY | J34: -1 | K34: =K33+J34 -> 31.5
A35: FEB 14TH | D35: Y | E35: N | F35: W | H35: B | I35: SELL | J35: 3.5 | K35: =K34+J35 -> 35
A36: FEB 6TH | C36: Y | E36: N | F36: W | H36: C | I36: SELL | J36: 3.5 | K36: =K35+J36 -> 38.5
A37: JAN 27TH | D37: Y | E37: Y | F37: W | H37: A | I37: BUY | J37: 2 | K37: =K36+J37 -> 40.5
A38: JAN 3RD | D38: Y | E38: N | F38: L | H38: B | I38: BUY | J38: -1 | K38: =K37+J38 -> 39.5
A39: JAN 3RD | D39: Y | E39: N | F39: W | H39: B | I39: BUY | J39: 2 | K39: =K38+J39 -> 41.5
I46: ROI BEFORE LOSSES | J46: =SUM(J2:J39) -> 41.5
...

Sheet 2022 US 30
A1: DATE | B1: FVP HIGH NODE | C1: FVP MED NODE | D1: FVP LOW NODE | E1: VWAP | F1: WIN OR LOSS | G1: AGAINST 4HR WICK | H1: RATING | I1: BUY OR SELL | J1: R:R | K1: NEWS WHILE IN TRADE
A2: DEC 22ND | D2: Y | E2: Y | F2: W | H2: A | I2: SELL | J2: 3.5
A3: DEC 1ST | D3: Y | E3: Y | F3: L | H3: A | I3: BUY
A4: NOV 16TH | B4: Y | E4: N | F4: L | H4: D | I4: BUY
A5: NOV 16TH | B5: Y | E5: N | F5: L | H5: D | I5: BUY
A6: NOV 8TH | D6: Y | E6: Y | F6: W | H6: A | I6: BUY | J6: 3.5
A7: NOV 2ND | D7: Y | E7: N | F7: L | H7: B | I7: SELL
A8: NOV 1ST | B8: Y | E8: N | F8: W | H8: D | I8: SELL | J8: 3.5
A9: OCT 20TH | C9: Y | E9: N | F9: W | H9: C | I9: BUY | J9: 3.5
A10: OCT 19TH | C10: Y | E10: N | F10: L | H10: C | I10: SELL
A11: SEP 23RD | D11: Y | E11: Y | F11: W | H11: A | I11: SELL | J11: 3.5
A12: SEP 16TH | D12: Y | E12: Y | F12: L | H12: A | I12: SELL
A13: SEP 8TH | B13: Y | E13: N | F13: W | H13: D | I13: BUY | J13: 2
A14: SEP 7TH | B14: Y | E14: N | F14: W | H14: D | I14: BUY | J14: 3.5
A15: SEP 5TH | B15: Y | E15: Y | F15: W | H15: B | I15: BUY | J15: 3.5
A16: SEP 1ST | B16: Y | E16: Y | F16: W | H16: B | I16: BUY | J16: 2
A17: AUG 24TH | B17: Y | E17: Y | F17: W | H17: B | I17: BUY | J17: 3.5
A18: AUG 9TH | D18: Y | E18: Y | F18: L | G18: Y | H18: F | I18: SELL
A19: AUG 4TH | D19: Y | E19: Y | F19: L | H19: A | I19: SELL
A20: AUG 1ST | B20: Y | E20: N | F20: L | H20: D | I20: BUY
A21: JULY 15TH | D21: Y | E21: Y | F21: W | H21: A | I21: BUY | J21: 2
A22: JULY 1ST | D22: Y | E22: N | F22: W | H22: B | I22: BUY | J22: 2
A23: JUNE 29TH | D23: Y | E23: Y | F23: L | H23: A | I23: BUY
A24: JUNE 21ST | B24: Y | E24: Y | F24: L | H24: D | I24: SELL
